<?xml version="1.0"?>
<robot
  name="cube">
  <link name="cube_1">
    <visual>
      <geometry>
        <box size="0.1 0.1 0.1"/>
      </geometry>
    </visual>
    <collision>
      <geometry>
        <box size="0.1 0.1 0.1"/>
      </geometry>
    </collision>
    <inertial>
      <mass value="0.1"/>
      <inertia ixx="0.01" ixy="0.0" ixz="0.0" iyy="0.01" iyz="0.0" izz="0.01"/>
      <origin xyz="0 0 0"/>
    </inertial>
  </link>
  <link name="cube_2">
    <visual>
      <origin xyz="0.1 0 0" rpy="0 0 0"/>
      <geometry>
        <box size="0.2 0.1 0.1"/>
      </geometry>
    </visual>
    <collision>
      <origin xyz="0.1 0 0" rpy="0 0 0"/>
      <geometry>
        <box size="0.2 0.1 0.1"/>
      </geometry>
    </collision>
    <inertial>
      <mass value="0.1"/>
      <inertia ixx="0.01" ixy="0.0" ixz="0.0" iyy="0.01" iyz="0.0" izz="0.01"/>
      <origin xyz="0 0 0"/>
    </inertial>
  </link>
  <joint name="cube_1_2_joint" type="revolute">
    <origin xyz="0.05 0 0" rpy="0 0 0"/>
    <axis xyz="0 0 1" rpy="0 0 0"/>
    <parent link="cube_1"/>
    <child link="cube_2"/>
  </joint>

</robot>
