<?xml version="1.0" ?>
<!-- =================================================================================== -->
<!-- |    This document was autogenerated by xacro from wsg_50_no_gelsight_finger.urdf.xacro | -->
<!-- |    EDITING THIS FILE BY HAND IS NOT RECOMMENDED                                 | -->
<!-- =================================================================================== -->
<robot name="wsg_50" xmlns:xacro="http://www.ros.org/wiki/xacro">
  <!-- MATERIALS -->
  <material name="Blue">
    <color rgba="0 0 1 1"/>
  </material>
  <material name="Red">
    <color rgba="1 0 0 1"/>
  </material>
  <material name="Green">
    <color rgba="0 1 0 1"/>
  </material>
  <material name="Yellow">
    <color rgba="1 1 0 1"/>
  </material>
  <material name="LightGrey">
    <color rgba="0.6 0.6 0.6 1.0"/>
  </material>
  <!-- END OF MATERIALS -->
  <!-- XACRO MACROS FOR VISUALS AND COLLISIONS -->
  <!-- END OF XACRO MACROS -->
  <link name="palm">
    <inertial>
      <origin rpy="0 0 0" xyz="0 0 0"/>
      <mass value="1"/>
      <inertia ixx="0.01" ixy="0" ixz="0" iyy="0.01" iyz="0" izz="0.01"/>
    </inertial>
    <visual>
      <geometry>
        <mesh filename="package://schunk_description/meshes/wsg_50/palm.stl"/>
      </geometry>
    </visual>
    <!-- The gripper itself -->
    <collision>
      <geometry>
        <box size="0.1453 0.0725 0.049"/>
      </geometry>
      <origin rpy="0 0 0" xyz="0.0 -0.0351 0.0"/>
    </collision>
    <!-- the larger mounting plate -->
    <collision>
      <geometry>
        <box size="0.05 0.0064 0.095"/>
      </geometry>
      <origin rpy="0 0 0" xyz="0.0 0.007 0"/>
    </collision>
  </link>
  <joint name="wsg_50_finger_left_joint" type="prismatic">
    <origin rpy="0 1.5707 0" xyz="0 -0.0719 0"/>
    <parent link="palm"/>
    <child link="wsg_50_finger_left_link"/>
    <axis xyz="0 0 -1"/>
    <!--<limit effort="10" lower="-0.001" upper="0.109" velocity="1.0"/>-->
  </joint>
  <link name="wsg_50_finger_left_link">
    <inertial>
      <origin rpy="0 0 0" xyz="0 0 0"/>
      <mass value="1"/>
      <inertia ixx="0.01" ixy="0" ixz="0" iyy="0.01" iyz="0" izz="0.01"/>
    </inertial>
    <!-- <xacro:left_finger_simple_visual/> -->
  </link>
  <joint name="wsg_50_finger_right_joint" type="prismatic">
    <origin rpy="3.1415 -1.5707 0" xyz="0 -0.0719 0.0"/>
    <parent link="palm"/>
    <child link="wsg_50_finger_right_link"/>
    <axis xyz="0 0 1"/>
    <!--<limit effort="10" lower="-0.001" upper="0.109" velocity="1.0"/> -->
  </joint>
  <link name="wsg_50_finger_right_link">
    <inertial>
      <origin rpy="0 0 0" xyz="0 0 0"/>
      <mass value="1"/>
      <inertia ixx="0.01" ixy="0" ixz="0" iyy="0.01" iyz="0" izz="0.01"/>
    </inertial>
    <!-- no gelsight collision geometry -->
  </link>
  <!-- extensions -->
  <transmission name="wsg_50_finger_left_trans">
    <type>transmission_interface/SimpleTransmission</type>
    <joint name="wsg_50_finger_left_joint"/>
    <actuator name="wsg_50_finger_left_motor">
      <hardwareInterface>EffortJointInterface</hardwareInterface>
      <mechanicalReduction>1</mechanicalReduction>
    </actuator>
  </transmission>
  <transmission name="wsg_50_finger_right_trans">
    <type>transmission_interface/SimpleTransmission</type>
    <joint name="wsg_50_finger_right_joint"/>
    <actuator name="wsg_50_finger_right_motor">
      <hardwareInterface>EffortJointInterface</hardwareInterface>
      <mechanicalReduction>1</mechanicalReduction>
    </actuator>
  </transmission>
</robot>
