<?xml version="1.0" ?>
<!-- =================================================================================== -->
<!-- |    This document was autogenerated by xacro from /u/wim/cturtle_wg_all/stacks/pr2_common/pr2_description/robots/pr2.urdf.xacro | -->
<!-- |    EDITING THIS FILE BY HAND IS NOT RECOMMENDED                                 | -->
<!-- =================================================================================== -->
<robot xmlns="http://drake.mit.edu"
 xmlns:xsi="http://www.w3.org/2001/XMLSchema-instance"
 xsi:schemaLocation="http://drake.mit.edu ../../doc/drakeURDF.xsd"
 xmlns:sensor="http://playerstage.sourceforge.net/gazebo/xmlschema/#sensor"
 xmlns:joint="http://playerstage.sourceforge.net/gazebo/xmlschema/#slider"
 xmlns:body="http://playerstage.sourceforge.net/gazebo/xmlschema/#body"
 xmlns:geom="http://playerstage.sourceforge.net/gazebo/xmlschema/#geom"
 xmlns:controller="http://playerstage.sourceforge.net/gazebo/xmlschema/#controller"
 xmlns:xacro="http://ros.org/wiki/xacro"
 xmlns:interface="http://playerstage.sourceforge.net/gazebo/xmlschema/#interface" name="pr2">

  <!-- materials for visualization -->
  <material name="Blue">
    <color rgba="0.0 0.0 0.8 1.0"/>
  </material>
  <material name="Green">
    <color rgba="0.0 0.8 0.0 1.0"/>
  </material>
  <material name="Grey">
    <color rgba="0.7 0.7 0.7 1.0"/>
  </material>
  <material name="Grey2">
    <color rgba="0.9 0.9 0.9 1.0"/>
  </material>
  <material name="Red">
    <color rgba="0.8 0.0 0.0 1.0"/>
  </material>
  <material name="White">
    <color rgba="1.0 1.0 1.0 1.0"/>
  </material>

  <link name="l_gripper_palm_link">
    <inertial>
      <mass value="0.58007"/>
      <origin rpy="0 0 0" xyz="0.06623 0.00053 -0.00119"/>
      <inertia ixx="0.00035223921" ixy="-0.00001580476" ixz="-0.00000091750" iyy="0.00067741312" iyz="-0.00000059554" izz="0.00086563316"/>
    </inertial>
    <visual>
      <origin rpy="0 0 0" xyz="0 0 0"/>
      <geometry>
        <mesh filename="pr2_description/meshes/gripper_v0/gripper_palm.stl"/>
      </geometry>
      <material name="Red"/>
    </visual>
    <collision>
      <origin rpy="0 0 0" xyz="0 0 0"/>
      <geometry>
        <mesh filename="pr2_description/meshes/gripper_v0/gripper_palm.stl"/>
      </geometry>
      <verbose value="Yes"/>
    </collision>
  </link>
  <joint name="l_gripper_led_joint" type="fixed">
    <!--  Need to check if we need a positive or negative Z term -->
    <origin xyz="0.0513 0.0 .0244"/>
    <parent link="l_gripper_palm_link"/>
    <child link="l_gripper_led_frame"/>
  </joint>
  <link name="l_gripper_led_frame"/>
  <joint name="l_gripper_motor_accelerometer_joint" type="fixed">
    <origin rpy="0 0 0" xyz="0 0 0"/>
    <parent link="l_gripper_palm_link"/>
    <child link="l_gripper_motor_accelerometer_link"/>
  </joint>
  <link name="l_gripper_motor_accelerometer_link">
    <inertial>
      <mass value="0.001"/>
      <origin rpy="0 0 0" xyz="0 0 0"/>
      <inertia ixx="0.001" ixy="0.0" ixz="0.0" iyy="0.001" iyz="0.0" izz="0.001"/>
    </inertial>
    <visual>
      <origin rpy="0 0 0" xyz="0 0 0"/>
      <geometry>
        <box size="0.001 0.001 0.001"/>
      </geometry>
    </visual>
    <collision>
      <origin rpy="0 0 0" xyz="0 0 0"/>
      <geometry>
        <box size="0.001 0.001 0.001"/>
      </geometry>
    </collision>
  </link>
  <joint name="l_gripper_tool_joint" type="fixed">
    <origin rpy="0 0 0" xyz="0.18 0 0"/>
    <parent link="l_gripper_palm_link"/>
    <child link="l_gripper_tool_frame"/>
  </joint>
  <link name="l_gripper_tool_frame"/>
  <joint name="l_gripper_l_finger_joint" type="revolute">
    <axis xyz="0 0 1"/>
    <limit effort="1000.0" lower="0.0" upper="0.548" velocity="0.5"/>
    <dynamics damping="0.2"/>
    <origin rpy="0 0 0" xyz="0.07691 0.01 0"/>
    <parent link="l_gripper_palm_link"/>
    <child link="l_gripper_l_finger_link"/>
  </joint>
  <link name="l_gripper_l_finger_link">
    <inertial>
      <mass value="0.17126"/>
      <origin rpy="0 0 0" xyz="0.03598 0.01730 -0.00164"/>
      <inertia ixx="0.00007756198" ixy="0.00000149095" ixz="-0.00000983385" iyy="0.00019708305" iyz="-0.00000306125" izz="0.00018105446"/>
    </inertial>
    <visual>
      <origin rpy="0 0 0" xyz="0 0 0"/>
      <geometry>
        <mesh filename="pr2_description/meshes/gripper_v0/l_finger.stl"/>
      </geometry>
      <material name="Grey"/>
    </visual>
    <collision>
      <origin rpy="0 0 0" xyz="0 0 0"/>
      <geometry>
        <mesh filename="pr2_description/meshes/gripper_v0/l_finger.stl"/>
      </geometry>
      <verbose value="Yes"/>
    </collision>
  </link>
  <joint name="l_gripper_r_finger_joint" type="revolute">
    <axis xyz="0 0 -1"/>
    <origin rpy="0 0 0" xyz="0.07691 -0.01 0"/>
    <limit effort="1000.0" lower="0.0" upper="0.548" velocity="0.5"/>
    <dynamics damping="0.2"/>
    <mimic joint="l_gripper_l_finger_joint" multiplier="1" offset="0"/>
    <parent link="l_gripper_palm_link"/>
    <child link="l_gripper_r_finger_link"/>
  </joint>
  <link name="l_gripper_r_finger_link">
    <inertial>
      <mass value="0.17389"/>
      <origin rpy="0 0 0" xyz="0.03576 -0.01736 -0.00095"/>
      <inertia ixx="0.00007738410" ixy="-0.00000209309" ixz="-0.00000836228" iyy="0.00019847383" iyz="0.00000246110" izz="0.00018106988"/>
    </inertial>
    <visual>
      <origin rpy="3.14159265359 0 0" xyz="0 0 0"/>
      <geometry>
        <mesh filename="pr2_description/meshes/gripper_v0/l_finger.stl"/>
      </geometry>
      <material name="Grey"/>
    </visual>
    <collision>
      <origin rpy="3.14159265359 0 0" xyz="0 0 0"/>
      <geometry>
        <mesh filename="pr2_description/meshes/gripper_v0/l_finger.stl"/>
      </geometry>
      <verbose value="Yes"/>
    </collision>
  </link>
  <joint name="l_gripper_l_parallel_root_joint" type="revolute">
    <axis xyz="0 0 1"/>
    <origin rpy="0 0 0" xyz="0.05891 0.031 0"/>
    <dynamics damping="0.2"/>
    <mimic joint="l_gripper_l_finger_joint" multiplier="1" offset="0"/>
    <parent link="l_gripper_palm_link"/>
    <child link="l_gripper_l_parallel_link"/>
    <limit effort="1000.0" lower="0.0" upper="0.548" velocity="0.5"/>
  </joint>
  <joint name="l_gripper_r_parallel_root_joint" type="revolute">
    <axis xyz="0 0 -1"/>
    <origin rpy="0 0 0" xyz="0.05891 -0.031 0"/>
    <dynamics damping="0.2"/>
    <mimic joint="l_gripper_l_finger_joint" multiplier="-1" offset="0"/>
    <parent link="l_gripper_palm_link"/>
    <child link="l_gripper_r_parallel_link"/>
    <limit effort="1000.0" lower="0.0" upper="0.548" velocity="0.5"/>
  </joint>
  <link name="l_gripper_l_parallel_link">
    <inertial>
      <mass value="0.17126"/>
      <origin rpy="0 0 0" xyz="0.03598 0.01730 -0.00164"/>
      <inertia ixx="0.00007756198" ixy="0.00000149095" ixz="-0.00000983385" iyy="0.00019708305" iyz="-0.00000306125" izz="0.00018105446"/>
    </inertial>
    <!--
      <visual>
        <origin xyz="${0.0914942479/2.0} 0 0" rpy="0 0 0.0541224233" />
        <geometry>
          <box size="${0.0914942479} 0.005 0.005" />
        </geometry>
        <material name="Green" />
      </visual>
-->
    <collision>
      <origin rpy="0 0 0.0541224233" xyz="0.04574712395 0 0"/>
      <geometry>
        <box size="0.0914942479 0.005 0.005"/>
      </geometry>
      <verbose value="Yes"/>
    </collision>
  </link>
  <link name="l_gripper_r_parallel_link">
    <inertial>
      <mass value="0.17389"/>
      <origin rpy="0 0 0" xyz="0.03576 -0.01736 -0.00095"/>
      <inertia ixx="0.00007738410" ixy="-0.00000209309" ixz="-0.00000836228" iyy="0.00019847383" iyz="0.00000246110" izz="0.00018106988"/>
    </inertial>
    <!--
      <visual>
        <origin xyz="${0.0914942479/2.0} 0 0" rpy="0 0 -0.0541224233" />
        <geometry>
          <box size="${0.0914942479} 0.005 0.005" />
        </geometry>
        <material name="Green" />
      </visual>
-->
    <collision>
      <origin rpy="0 0 -0.0541224233" xyz="0.04574712395 0 0"/>
      <geometry>
        <box size="0.0914942479 0.005 0.005"/>
      </geometry>
      <verbose value="Yes"/>
    </collision>
  </link>
  <joint name="l_gripper_l_finger_tip_joint" type="revolute">
    <axis xyz="0 0 -1"/>
    <origin rpy="0 0 0" xyz="0.09137 0.00495 0"/>
    <limit effort="1000.0" lower="0.0" upper="0.548" velocity="0.5"/>
    <dynamics damping="0.01"/>
    <mimic joint="l_gripper_l_finger_joint" multiplier="1" offset="0"/>
    <parent link="l_gripper_l_finger_link"/>
    <child link="l_gripper_l_finger_tip_link"/>
  </joint>
  <link name="l_gripper_l_finger_tip_link">
    <inertial>
      <mass value="0.04419"/>
      <origin rpy="0 0 0" xyz="0.00423 0.00284 0.0"/>
      <inertia ixx="0.00000837047" ixy="0.00000583632" ixz="0.0" iyy="0.00000987067" iyz="0.0" izz="0.00001541768"/>
    </inertial>
    <visual>
      <origin rpy="0 0 0" xyz="0 0 0"/>
      <geometry>
        <mesh filename="pr2_description/meshes/gripper_v0/l_finger_tip.stl"/>
      </geometry>
      <material name="Green"/>
    </visual>
    <collision>
      <origin rpy="0 0 0" xyz="0 0 0"/>
      <geometry>
        <mesh filename="pr2_description/meshes/gripper_v0/l_finger_tip.stl"/>
      </geometry>
      <verbose value="Yes"/>
    </collision>
  </link>
  <joint name="l_gripper_r_finger_tip_joint" type="revolute">
    <axis xyz="0 0 1"/>
    <origin rpy="0 0 0" xyz="0.09137 -0.00495 0"/>
    <limit effort="1000.0" lower="0.0" upper="0.548" velocity="0.5"/>
    <dynamics damping="0.01"/>
    <mimic joint="l_gripper_l_finger_joint" multiplier="1" offset="0"/>
    <parent link="l_gripper_r_finger_link"/>
    <child link="l_gripper_r_finger_tip_link"/>
  </joint>
  <link name="l_gripper_r_finger_tip_link">
    <inertial>
      <mass value="0.04419"/>
      <origin rpy="0 0 0" xyz="0.00423 -0.00284 0.0"/>
      <inertia ixx="0.00000837047" ixy="-0.00000583632" ixz="0.0" iyy="0.00000987067" iyz="0.0" izz="0.00001541768"/>
    </inertial>
    <visual>
      <origin rpy="3.14159265359 0 0" xyz="0 0 0"/>
      <geometry>
        <mesh filename="pr2_description/meshes/gripper_v0/l_finger_tip.stl"/>
      </geometry>
      <material name="Green"/>
    </visual>
    <collision>
      <origin rpy="3.14159265359 0 0" xyz="0 0 0"/>
      <geometry>
        <mesh filename="pr2_description/meshes/gripper_v0/l_finger_tip.stl"/>
      </geometry>
      <verbose value="Yes"/>
    </collision>
  </link>
  <gazebo reference="l_gripper_l_finger_link">
    <turnGravityOff>true</turnGravityOff>
    <sensor:contact name="l_gripper_l_finger_contact_sensor">
      <geom>l_gripper_l_finger_link_geom</geom>
      <updateRate>100.0</updateRate>
      <controller:gazebo_ros_bumper name="l_gripper_l_finger_gazebo_ros_bumper_controller" plugin="libgazebo_ros_bumper.so">
        <alwaysOn>true</alwaysOn>
        <updateRate>100.0</updateRate>
        <bumperTopicName>l_gripper_l_finger_bumper</bumperTopicName>
        <interface:bumper name="l_gripper_l_finger_gazebo_ros_bumper_iface"/>
      </controller:gazebo_ros_bumper>
    </sensor:contact>
    <mu1 value="500.0"/>
    <mu2 value="500.0"/>
    <kp value="1000000.0"/>
    <kd value="1.0"/>
    <material value="PR2/Grey"/>
    <!-- for "${prefix}_l_finger_joint"-->
  </gazebo>
  <gazebo reference="l_gripper_l_finger_joint">
    <stopKd value="1.0"/>
    <stopKp value="10000000.0"/>
    <fudgeFactor value="1.0"/>
    <provideFeedback value="true"/>
  </gazebo>
  <gazebo reference="l_gripper_r_finger_link">
    <turnGravityOff>true</turnGravityOff>
    <sensor:contact name="l_gripper_r_finger_contact_sensor">
      <geom>l_gripper_r_finger_link_geom</geom>
      <updateRate>100.0</updateRate>
      <controller:gazebo_ros_bumper name="l_gripper_r_finger_gazebo_ros_bumper_controller" plugin="libgazebo_ros_bumper.so">
        <alwaysOn>true</alwaysOn>
        <updateRate>100.0</updateRate>
        <bumperTopicName>l_gripper_r_finger_bumper</bumperTopicName>
        <interface:bumper name="l_gripper_r_finger_gazebo_ros_bumper_iface"/>
      </controller:gazebo_ros_bumper>
    </sensor:contact>
    <mu1 value="500.0"/>
    <mu2 value="500.0"/>
    <kp value="1000000.0"/>
    <kd value="1.0"/>
    <material value="PR2/Grey"/>
  </gazebo>
  <gazebo reference="l_gripper_r_finger_joint">
    <stopKd value="1.0"/>
    <stopKp value="10000000.0"/>
    <fudgeFactor value="1.0"/>
    <provideFeedback value="true"/>
  </gazebo>
  <gazebo reference="l_gripper_l_finger_tip_link">
    <turnGravityOff>true</turnGravityOff>
    <selfCollide>false</selfCollide>
    <sensor:contact name="l_gripper_l_finger_tip_contact_sensor">
      <geom>l_gripper_l_finger_tip_link_geom</geom>
      <updateRate>100.0</updateRate>
      <controller:gazebo_ros_bumper name="l_gripper_l_finger_tip_gazebo_ros_bumper_controller" plugin="libgazebo_ros_bumper.so">
        <alwaysOn>true</alwaysOn>
        <updateRate>100.0</updateRate>
        <bumperTopicName>l_gripper_l_finger_tip_bumper</bumperTopicName>
        <interface:bumper name="l_gripper_l_finger_tip_gazebo_ros_bumper_iface"/>
      </controller:gazebo_ros_bumper>
    </sensor:contact>
    <mu1 value="500.0"/>
    <mu2 value="500.0"/>
    <kp value="10000000.0"/>
    <kd value="1.0"/>
    <material value="PR2/Grey"/>
  </gazebo>
  <gazebo reference="l_gripper_l_finger_tip_joint">
    <stopKd value="1.0"/>
    <stopKp value="10000000.0"/>
    <fudgeFactor value="1.0"/>
    <provideFeedback value="true"/>
  </gazebo>
  <gazebo reference="l_gripper_r_finger_tip_link">
    <turnGravityOff>true</turnGravityOff>
    <selfCollide>false</selfCollide>
    <sensor:contact name="l_gripper_r_finger_tip_contact_sensor">
      <geom>l_gripper_r_finger_tip_link_geom</geom>
      <updateRate>100.0</updateRate>
      <controller:gazebo_ros_bumper name="l_gripper_r_finger_tip_gazebo_ros_bumper_controller" plugin="libgazebo_ros_bumper.so">
        <alwaysOn>true</alwaysOn>
        <updateRate>100.0</updateRate>
        <bumperTopicName>l_gripper_r_finger_tip_bumper</bumperTopicName>
        <interface:bumper name="l_gripper_r_finger_tip_gazebo_ros_bumper_iface"/>
      </controller:gazebo_ros_bumper>
    </sensor:contact>
    <mu1 value="500.0"/>
    <mu2 value="500.0"/>
    <kp value="10000000.0"/>
    <kd value="1.0"/>
    <material value="PR2/Grey"/>
  </gazebo>
  <gazebo>
    <controller:gazebo_ros_p3d name="p3d_l_gripper_l_finger_controller" plugin="libgazebo_ros_p3d.so">
      <alwaysOn>true</alwaysOn>
      <updateRate>100.0</updateRate>
      <bodyName>l_gripper_l_finger_link</bodyName>
      <topicName>l_gripper_l_finger_pose_ground_truth</topicName>
      <gaussianNoise>0.0</gaussianNoise>
      <frameName>base_link</frameName>
      <interface:position name="p3d_l_gripper_l_finger_position_iface"/>
    </controller:gazebo_ros_p3d>
    <controller:gazebo_ros_f3d name="f3d_l_gripper_l_finger_controller" plugin="libgazebo_ros_f3d.so">
      <alwaysOn>true</alwaysOn>
      <updateRate>100.0</updateRate>
      <bodyName>l_gripper_l_finger_link</bodyName>
      <topicName>l_gripper_l_finger_force_ground_truth</topicName>
      <frameName>l_gripper_l_finger_link</frameName>
      <interface:position name="f3d_l_gripper_l_finger_force_iface"/>
    </controller:gazebo_ros_f3d>
  </gazebo>
  <gazebo reference="l_gripper_r_finger_tip_joint">
    <stopKd value="1.0"/>
    <stopKp value="10000000.0"/>
    <fudgeFactor value="1.0"/>
    <provideFeedback value="true"/>
  </gazebo>
  <gazebo>
    <joint:hinge name="l_gripper_r_parallel_tip_joint">
      <body1>l_gripper_r_parallel_link</body1>
      <body2>l_gripper_r_finger_tip_link</body2>
      <anchor>l_gripper_r_finger_tip_link</anchor>
      <axis>0 0 1</axis>
      <anchorOffset>-0.018 -0.021 0</anchorOffset>
    </joint:hinge>
    <joint:hinge name="l_gripper_l_parallel_tip_joint">
      <body1>l_gripper_l_parallel_link</body1>
      <body2>l_gripper_l_finger_tip_link</body2>
      <anchor>l_gripper_l_finger_tip_link</anchor>
      <axis>0 0 1</axis>
      <anchorOffset>-0.018 0.021 0</anchorOffset>
    </joint:hinge>
    <joint:slider name="l_gripper_joint">
      <body1>l_gripper_l_finger_tip_link</body1>
      <body2>l_gripper_r_finger_tip_link</body2>
      <anchor>l_gripper_r_finger_tip_link</anchor>
      <axis>0 1 0</axis>
    </joint:slider>
  </gazebo>
  <gazebo reference="l_gripper_l_parallel_link">
    <turnGravityOff>true</turnGravityOff>
    <material value="PR2/Red"/>
  </gazebo>
  <gazebo reference="l_gripper_r_parallel_link">
    <turnGravityOff>true</turnGravityOff>
    <material value="PR2/Red"/>
  </gazebo>
  <joint name="l_gripper_joint" type="prismatic">
    <parent link="l_gripper_r_finger_tip_link"/>
    <child link="l_gripper_l_finger_tip_frame"/>
    <axis xyz="0 1 0"/>
    <dynamics damping="100.0"/>
    <limit effort="1000.0" lower="0.0" upper="0.09" velocity="0.2"/>
    <safety_controller k_position="20.0" k_velocity="5000.0" soft_lower_limit="-0.01" soft_upper_limit="0.088"/>
  </joint>
  <link name="l_gripper_l_finger_tip_frame"/>
  <gazebo reference="l_gripper_palm_link">
    <turnGravityOff>true</turnGravityOff>
    <sensor:contact name="l_gripper_palm_contact_sensor">
      <geom>l_gripper_palm_link_geom</geom>
      <updateRate>100.0</updateRate>
      <controller:gazebo_ros_bumper name="l_gripper_palm_gazebo_ros_bumper_controller" plugin="libgazebo_ros_bumper.so">
        <alwaysOn>true</alwaysOn>
        <updateRate>100.0</updateRate>
        <bumperTopicName>l_gripper_palm_bumper</bumperTopicName>
        <interface:bumper name="l_gripper_palm_gazebo_ros_bumper_iface"/>
      </controller:gazebo_ros_bumper>
    </sensor:contact>
    <material value="PR2/Grey"/>
  </gazebo>
  <gazebo>
    <controller:gazebo_ros_p3d name="p3d_l_gripper_palm_controller" plugin="libgazebo_ros_p3d.so">
      <alwaysOn>true</alwaysOn>
      <updateRate>100.0</updateRate>
      <bodyName>l_gripper_palm_link</bodyName>
      <topicName>l_gripper_palm_pose_ground_truth</topicName>
      <xyzOffsets>0 0 0</xyzOffsets>
      <rpyOffsets>0 0 0</rpyOffsets>
      <gaussianNoise>0.0</gaussianNoise>
      <frameName>map</frameName>
      <interface:position name="p3d_l_gripper_palm_position_iface"/>
    </controller:gazebo_ros_p3d>
  </gazebo>
  <transmission name="l_gripper_trans" type="PR2GripperTransmission">
    <actuator name="l_gripper_motor"/>
    <gap_joint L0="0.0375528" a="0.0683698" b="0.0433849" gear_ratio="40.095" h="0.0" mechanical_reduction="1.0" name="l_gripper_joint" phi0="0.518518122146" r="0.0915" screw_reduction="0.004" t0="-0.0001914" theta0="0.0628824676201"/>
    <!-- if a gazebo joint exists as [l|r]_gripper_joint, use this tag to have
           gripper transmission apply torque directly to prismatic joint -->
    <use_simulated_gripper_joint/>
    <passive_joint name="l_gripper_l_finger_joint"/>
    <passive_joint name="l_gripper_r_finger_joint"/>
    <passive_joint name="l_gripper_r_finger_tip_joint"/>
    <passive_joint name="l_gripper_l_finger_tip_joint"/>
    <passive_joint name="l_gripper_r_parallel_root_joint"/>
    <passive_joint name="l_gripper_l_parallel_root_joint"/>
  </transmission>

</robot>
